<?xml version="1.0"?>
<robot name="simple_robot" xmlns:xacro="http://wiki.ros.org/xacro">

  <!-- ===================== 1. 提取所有参数 ===================== -->
  <xacro:property name="base_length" value="0.4"/>
  <xacro:property name="base_width" value="0.2"/>
  <xacro:property name="base_height" value="0.1"/>

  <xacro:property name="wheel_radius" value="0.05"/>
  <xacro:property name="wheel_length" value="0.03"/>

  <xacro:property name="caster_radius" value="0.05"/>

  <xacro:property name="laser_radius" value="0.02"/>
  <xacro:property name="laser_length" value="0.05"/>


  <!-- ===================== 2. 轮子宏 ===================== -->
  <xacro:macro name="wheel_macro" params="name parent x y z">
    <link name="${name}_link">
      <visual>
        <origin xyz="0 0 0" rpy="1.5708 0 0"/>
        <geometry>
          <cylinder radius="${wheel_radius}" length="${wheel_length}"/>
        </geometry>
        <material name="black">
          <color rgba="0 0 0 1"/>
        </material>
      </visual>
      <collision>
        <origin xyz="0 0 0" rpy="1.5708 0 0"/>
        <geometry>
          <cylinder radius="${wheel_radius}" length="${wheel_length}"/>
        </geometry>
      </collision>
    </link>

    <joint name="${name}_joint" type="revolute">
      <origin xyz="${x} ${y} ${z}"/>
      <parent link="${parent}"/>
      <child link="${name}_link"/>
      <axis xyz="0 1 0"/>
      <limit effort="10" velocity="10" lower="-1e6" upper="1e6"/>
    </joint>
  </xacro:macro>


  <!-- ===================== 3. 激光雷达宏 ===================== -->
  <xacro:macro name="laser_macro" params="name parent x y z">
    <link name="${name}_link">
      <visual>
        <geometry>
          <cylinder radius="${laser_radius}" length="${laser_length}"/>
        </geometry>
        <material name="red">
          <color rgba="1 0 0 1"/>
        </material>
      </visual>
      <collision>
        <geometry>
          <cylinder radius="${laser_radius}" length="${laser_length}"/>
        </geometry>
      </collision>
    </link>

    <joint name="${name}_joint" type="fixed">
      <origin xyz="${x} ${y} ${z}"/>
      <parent link="${parent}"/>
      <child link="${name}_link"/>
    </joint>
  </xacro:macro>


  <!-- ===================== 4. 底盘 ===================== -->
  <link name="base_link">
    <visual>
      <geometry>
        <box size="${base_length} ${base_width} ${base_height}"/>
      </geometry>
      <material name="blue">
        <color rgba="0 0 1 1"/>
      </material>
    </visual>
    <collision>
      <geometry>
        <box size="${base_length} ${base_width} ${base_height}"/>
      </geometry>
    </collision>
  </link>


  <!-- ===================== 5. 左右轮（调用宏） ===================== -->
  <xacro:wheel_macro name="wheel_left" parent="base_link" x="-0.15" y="-0.1" z="-0.05"/>
  <xacro:wheel_macro name="wheel_right" parent="base_link" x="-0.15" y="0.1" z="-0.05"/>


  <!-- ===================== 6. 万向轮 ===================== -->
  <link name="caster_link">
    <visual>
      <geometry>
        <sphere radius="${caster_radius}"/>
      </geometry>
      <material name="gray">
        <color rgba="0.5 0.5 0.5 1"/>
      </material>
    </visual>
    <collision>
      <geometry>
        <sphere radius="${caster_radius}"/>
      </geometry>
    </collision>
  </link>

  <joint name="caster_joint" type="fixed">
    <origin xyz="0.15 0 -0.05"/>
    <parent link="base_link"/>
    <child link="caster_link"/>
  </joint>


  <!-- ===================== 7. 激光雷达（调用宏 → fixed 固定） ===================== -->
  <xacro:laser_macro name="laser" parent="base_link" x="0" y="0" z="0.1"/>

</robot>
